Workbook

Sheet Quote-R0
A1: Estimate for Renovation Works
C2: Client Address: Tower-A, Ascendas IT Park, Vega, Floor 12, , The V, Plot no 17, Inorbit Mall Rd, Madhapur, Telangana 500081 | E2: Client:
A7: #320, Fifth Floor, East Avenue, fifth floor, VI Phase, Ayyappa Society, Madhapur, Hyderabad, Telangana - 500081, Phone 040-40047888. | C7: Q.No: C2604-110 | E7: Date: 30-04-2026
A8: S.NO. | B8: ITEMS/ DESCRIPTION/ FINISHES | C8: UNIT | D8: QUANTITY | E8: RATE | F8: AMOUNT | H8: material | I8: Service
N9: electrical
B10: Dismantling Work | L10: service | M10: mAterial | N10: interior
A11: 1.1 | B11: Partitions: Dismantling of existing Gypsum/Glass/Wooden partitions wherever required and stacking debris within 10 meters from the work area. Providing and fixing skirting as per site requirement. | C11: Sq.fts | D11: ='Details-R0'!G20 -> 3477.5 | E11: 28 | F11: =E11*D11 -> 97370
A12: 2 | B12: Brick Wall: Dismantling of existing brick wall and lintels where ever necessary and stacking the debris with a lead of 10mts away from the dismantled area and Repairs of the areas. | C12: LS | D12: ='Details-R0'!G24 -> 1 | E12: 10000 | F12: =E12*D12 -> 10000
A13: 2.9 | B13: Column Cladding: Dismantling of existing column cladding wherever required, including stacking of debris within 10 meters from the dismantled area and making good the damaged areas after completion of work. | C13: Sq.fts | D13: ='Details-R0'!G31 -> 750 | E13: 25 | F13: =E13*D13 -> 18750
A14: 3.8 | B14: Wall Paneling: Dismantling of existing wall laminate and paneling wherever required, including stacking of debris within 10 meters from the dismantled area and making good the damaged areas after completion of work. | C14: Sq.fts | D14: ='Details-R0'!G37 -> 507.375 | E14: 27 | F14: =E14*D14 -> 13699.125
A15: 4.7 | B15: False ceiling: Dismantling of existing Gypsum/PVC/Grid false ceiling wherever required, including stacking of debris within 10 meters from the dismantled area and making good the damaged areas after completion of work. | C15: Sq.fts | D15: ='Details-R0'!G54 -> 1391 | E15: 19 | F15: =E15*D15 -> 26429
A16: 5.6 | B16: Furniture: Removing of existing furniture, partitions, wiring, switch boards, etc., and stacking the materials at ground floor as per site requirement. | C16: LS | D16: ='Details-R0'!G58 -> 1 | E16: 250000 | F16: =E16*D16 -> 250000
A17: 6.5 | B17: Carpet: Removing of existing carpet flooring including adhesive residue wherever required, and stacking of debris within 10 meters from the work area as per site instructions. | C17: LS | D17: ='Details-R0'!G66 -> 1 | E17: 30000 | F17: =E17*D17 -> 30000
A18: 8 | B18: Lights: Removing of existing light fittings wherever required and stacking the materials as per site requirement. | C18: LS | D18: ='Details-R0'!G70 -> 1 | E18: 25000 | F18: =E18*D18 -> 25000
A19: 9 | B19: Shifting of debris/materials such as carpet, gypsum material, glass partitions, cabin tables, etc., from 13th floor to ground floor as per site requirement. | C19: LS | D19: ='Details-R0'!G74 -> 1 | E19: 35000 | F19: =E19*D19 -> 35000
A20: 10 | B20: Carting of dismantled debris from the stacked area and disposing the same approximately 10 km away from the site using tractor vehicle. | C20: Load | D20: ='Details-R0'!G78 -> 15 | E20: 5000 | F20: =E20*D20 -> 75000
A21: 11 | B21: Removing of existing doors and door frames and stacking the materials at the location instructed by the site in-charge within 100 meters from the dismantled area. | C21: No's | D21: ='Details-R0'!G88 -> 13 | E21: 2800 | F21: =E21*D21 -> 36400
A22: 12 | B22: Pedestal Removal: Carefully dismantling and removing the existing pedestal from the site, including shifting debris and disposing of waste materials as per site conditions. | C22: LS | D22: 1 | E22: 75000 | F22: =E22*D22 -> 75000 | H22: =137*2*250 -> 68500
B24: Civil Works
A25: 1 | B25: Granite Work
A26: 1.1 | B26: Granite for Counter Top (Pantry Area): Providing and fixing granite countertop with edge polishing and moulding, fixed over plywood/WPC on MS base frame using approved adhesives. The rate includes all materials, hardware, fittings, labour, and installation, complete as per design and instructions of the Architect/Engineer. | C26: Sq.fts | D26: ='Details-R0'!G96 -> 28.5 | E26: 650 | F26: =E26*D26 -> 18525
A27: 2 | B27: Plumbing Works
A28: 2.1 | B28: Plumbing Works Providing and laying of pipeline for pantry connection from 11th floor to ground floor, including all required fittings, supports, cutting, chasing, jointing, testing and fixing complete as per site requirement. | C28: LS | D28: ='Details-R0'!G102 -> 1 | E28: 100000 | F28: =E28*D28 -> 100000 | H28: Installation-1000-2000
A29: 3 | B29: Sanitary Fixtures
A30: 3.1 | B30: SS Sink- 24"X18"X8" - AS per selection | C30: No's | D30: ='Details-R0'!G107 -> 1 | E30: 11500 | F30: =E30*D30 -> 11500 | H30: 8750
A31: 3.2 | B31: Sink Cock : Brand: Parryware/Cera and other accessories | C31: No's | D31: ='Details-R0'!G111 -> 1 | E31: 6500 | F31: =E31*D31 -> 6500 | H31: 1500-1800
A32: 4 | B32: Floor Chipping
A33: 4.1 | B33: Drainage Pipeline: Floor chipping for drain pipeline from pantry room to duct area, including debris removal. Cutting and refixing of metal door for 6" opening as per site requirement. | C33: LS | D33: ='Details-R0'!G115 -> 1 | E33: 20000 | F33: =E33*D33 -> 20000
A34: 5 | B34: Flooring Work
A35: 5.1 | B35: Flooring Work near the entrance: Floor cutting and making new flooring for mat and floor finish, including skirting work at dismantled brick wall area as per site requirement. | C35: LS | D35: ='Details-R0'!G119 -> 1 | E35: 22500 | F35: =E35*D35 -> 22500
A36: 6 | B36: Trap Door
A37: 6.1 | B37: Providing and fixing of trap door including all necessary hardware, fittings and finishing complete as per site requirement. | C37: LS | D37: ='Details-R0'!G123 -> 1 | E37: 4000 | F37: =E37*D37 -> 4000
B39: Modular Glass Works
A40: 1 | B40: Glass Work
A41: 1.1 | B41: Glass Partition - Upto 2100mm height from FFL Supply and installation of 10 mm toughened glass partition (OTIC/Taiton/Dolysia/Ozone or equivalent) in 45 x 25 mm anodized aluminum sections. Ply support to be provided for door frames as required, as per drawings. | C41: Sq.fts | D41: 732 | E41: 520 | F41: =E41*D41 -> 380640 | H41: 385 | I41: 325
A42: 1.2 | B42: Frosted Glass Film: Supply and application of frosted glass film on glass surface, including proper surface cleaning and fixing without bubbles, complete with all materials and labour. | C42: Sq.fts | D42: 522 | E42: 150 | F42: =E42*D42 -> 78300 | H42: 75
A43: 1.3 | B43: Glass Door : Single Leaf Supply and installation of single leaf aluminium stile glass door with 45mm x 45mm frame and 65mm x 35mm shutter, finished in black anodized finish. Door fitted with 10mm thick clear toughened glass and required glass hardware of OTIC/Taiton/Dolysia/Ozone or equivalent, complete as per specifications.
B44: Opening Size : W 900mm X H 2100mm Nos. Per Door | C44: No's | D44: ='Details-R0'!G159 -> 8 | E44: 46800 | F44: =E44*D44 -> 374400 | H44: 29500
A45: 1.4 | B45: Glass Door : Double Leaf Supply and installation of single leaf aluminium stile glass door with 45mm x 45mm frame and 65mm x 35mm shutter, finished in black anodized finish. Door fitted with 10mm thick clear toughened glass and required glass hardware of OTIC/Taiton/Dolysia/Ozone or equivalent, complete as per specifications.
B46: Opening Size : W 2700mm X H 2100mm Nos. Per Door | C46: No's | D46: ='Details-R0'!G163 -> 1 | E46: 97500 | F46: =E46*D46 -> 97500 | H46: =37500+37500 -> 75000
...

Sheet Details-R0
A1: S.No | B1: Description | C1: Units | D1: No's | E1: L | F1: W | G1: Qty
B3: Dismantling
B4: Paritions
B5: Reception Area | C5: Sqfts | D5: 1 | E5: 5.5 | F5: 10 | G5: =F5*E5*D5 -> 55
C6: Sqfts | D6: 1 | E6: 25.5 | F6: 10 | G6: =F6*E6*D6 -> 255
C7: Sqfts | D7: 1 | E7: 18 | F7: 10 | G7: =F7*E7*D7 -> 180
C8: Sqfts | D8: 1 | E8: 25.75 | F8: 10 | G8: =F8*E8*D8 -> 257.5
B9: Travel Desk/Visiting Dir | C9: Sqfts | D9: 2 | E9: 11.25 | F9: 10 | G9: =F9*E9*D9 -> 225
C10: Sqfts | D10: 2 | E10: 22.25 | F10: 10 | G10: =F10*E10*D10 -> 445
B11: Interview Rooms | C11: Sqfts | D11: 2 | E11: 11.25 | F11: 10 | G11: =F11*E11*D11 -> 225
C12: Sqfts | D12: 2 | E12: 18.25 | F12: 10 | G12: =F12*E12*D12 -> 365
B13: Cabins | C13: Sqfts | D13: 3 | E13: 11.25 | F13: 10 | G13: =F13*E13*D13 -> 337.5
C14: Sqfts | D14: 2 | E14: 26.25 | F14: 10 | G14: =F14*E14*D14 -> 525
B15: Utility Beside Room | C15: Sqfts | D15: 1 | E15: 9.5 | F15: 10 | G15: =F15*E15*D15 -> 95
B16: 8Pax Conference Room | C16: Sqfts | D16: 1 | E16: 10.75 | F16: 10 | G16: =F16*E16*D16 -> 107.5
B17: Conference Room | C17: Sqfts | D17: 1 | E17: 27.5 | F17: 10 | G17: =F17*E17*D17 -> 275
C18: Sqfts | D18: 1 | E18: 13 | F18: 10 | G18: =F18*E18*D18 -> 130
B20: TOTAL | G20: =SUM(G5:G19) -> 3477.5
B21: Brick Wall
B22: Reception Area | C22: Sqfts | D22: 1 | E22: 5.5 | F22: 10 | G22: =F22*E22*D22 -> 55
B24: TOTAL | G24: 1
B25: Columns
B26: Reception Area | C26: Sqfts | D26: 8 | E26: 2.5 | F26: 10 | G26: =F26*E26*D26 -> 200
C27: Sqfts | D27: 8 | E27: 2.5 | F27: 10 | G27: =F27*E27*D27 -> 200
C28: Sqfts | D28: 7 | E28: 2.5 | F28: 10 | G28: =F28*E28*D28 -> 175
C29: Sqfts | D29: 7 | E29: 2.5 | F29: 10 | G29: =F29*E29*D29 -> 175
B31: TOTAL | G31: =SUM(G26:G30) -> 750
B32: Wall Panelling
B33: Linear Work Station Area | C33: Sqfts | D33: 1 | E33: 4 | F33: 8.25 | G33: =F33*E33*D33 -> 33
C34: Sqfts | D34: 1 | E34: 51.5 | F34: 8.25 | G34: =F34*E34*D34 -> 424.875
B35: Linear Work Station Area-Corridor | C35: Sqfts | D35: 1 | E35: 6 | F35: 8.25 | G35: =F35*E35*D35 -> 49.5
B37: TOTAL | G37: =SUM(G33:G36) -> 507.375
B38: False Ceiling
B39: Reception Area | C39: Sqfts | D39: 1 | E39: 5.5 | F39: 4 | G39: =F39*E39*D39 -> 22
C40: Sqfts | D40: 1 | E40: 25.5 | F40: 4 | G40: =F40*E40*D40 -> 102
C41: Sqfts | D41: 1 | E41: 18 | F41: 4 | G41: =F41*E41*D41 -> 72
C42: Sqfts | D42: 1 | E42: 25.75 | F42: 4 | G42: =F42*E42*D42 -> 103
B43: Travel Desk/Visiting Dir | C43: Sqfts | D43: 2 | E43: 11.25 | F43: 4 | G43: =F43*E43*D43 -> 90
C44: Sqfts | D44: 2 | E44: 22.25 | F44: 4 | G44: =F44*E44*D44 -> 178
B45: Interview Rooms | C45: Sqfts | D45: 2 | E45: 11.25 | F45: 4 | G45: =F45*E45*D45 -> 90
...
